<mujoco model="Dextra_lowerbody">
  <compiler angle="radian" meshdir="meshes"/>

  <asset>
    <texture type="2d" name="groundplane" builtin="checker" mark="edge"
             rgb1="0.7 0.7 0.7" rgb2="0.9 0.9 0.9" markrgb="0 0 0" width="300" height="300"/>
    <material name="groundplane" texture="groundplane" texuniform="true" texrepeat="5 5" reflectance="0.1"/>
    <mesh name="base_link" content_type="model/stl" file="base_link.stl" scale="0.001 0.001 0.001"/>
    <mesh name="L_HipYaw_Link_1" content_type="model/stl" file="L_HipYaw_Link_1.stl" scale="0.001 0.001 0.001"/>
    <mesh name="L_HipRoll_Link_1" content_type="model/stl" file="L_HipRoll_Link_1.stl" scale="0.001 0.001 0.001"/>
    <mesh name="L_Thigh_Link_1" content_type="model/stl" file="L_Thigh_Link_1.stl" scale="0.001 0.001 0.001"/>
    <mesh name="L_Calf_Link_1" content_type="model/stl" file="L_Calf_Link_1.stl" scale="0.001 0.001 0.001"/>
    <mesh name="L_AnklePitch_Link_1" content_type="model/stl" file="L_AnklePitch_Link_1.stl" scale="0.001 0.001 0.001"/>
    <mesh name="L_AnkleRoll_Link_1" content_type="model/stl" file="L_AnkleRoll_Link_1.stl" scale="0.001 0.001 0.001"/>
    <mesh name="R_HipYaw_Link_1" content_type="model/stl" file="R_HipYaw_Link_1.stl" scale="0.001 0.001 0.001"/>
    <mesh name="R_HipRoll_Link_1" content_type="model/stl" file="R_HipRoll_Link_1.stl" scale="0.001 0.001 0.001"/>
    <mesh name="R_Thigh_Link_1" content_type="model/stl" file="R_Thigh_Link_1.stl" scale="0.001 0.001 0.001"/>
    <mesh name="R_Calf_Link_1" content_type="model/stl" file="R_Calf_Link_1.stl" scale="0.001 0.001 0.001"/>
    <mesh name="R_AnklePitch_Link_1" content_type="model/stl" file="R_AnklePitch_Link_1.stl" scale="0.001 0.001 0.001"/>
    <mesh name="R_AnkleRoll_Link_1" content_type="model/stl" file="R_AnkleRoll_Link_1.stl" scale="0.001 0.001 0.001"/>
  </asset>

  <worldbody>
    <body name="base_link" pos="0 0 0.2865">
    <inertial pos="0.001657726421881901 4.613099704676144e-07 0.0282202162110548" quat="0.5 0.5 0.5 0.5" mass="0.36768618241131146" diaginertia="0.000714 0.000728 0.001076"/>
    <freejoint name="base"/>
    <geom type="mesh" contype="0" conaffinity="0" group="1" rgba="0.2 0.2 0.2 1" mesh="base_link"/>
    <geom type="mesh" group="0" mesh="base_link"/>
      <body name="L_HipYaw_Link_1" pos="0.015 0.03755 -0.03694">
        <inertial pos="-0.000221103 9.1293e-07 -0.0123156" quat="0.5 0.5 0.5 0.5" mass="0.00826277" diaginertia="4e-06 3e-06 1e-06"/>
        <joint name="L_HipYaw_Joint" pos="0 0 0" axis="0 0 1" limited="true" range="-0.7854 0.7854" stiffness="0.5" damping="0.5" armature="0.00054"/>
        <geom pos="-0.015 -0.03755 0.03694" contype="0" conaffinity="0" group="1" quat="1 0 0 0" rgba="0.2 0.2 0.2 1" type="mesh" mesh="L_HipYaw_Link_1"/>
        <body name="L_HipRoll_Link_1" pos="-0.024 4e-06 -0.030366">
          <inertial pos="0.00326869 0.000444016 -0.0160343" quat="0.509544 0.479923 0.488498 0.520969" mass="0.100867" diaginertia="8.50201e-05 6.71243e-05 3.48556e-05"/>
          <joint name="L_HipRoll_Joint" pos="0 0 0" axis="1 0 0" limited="true" range="-0.7854 0.7854" stiffness="0.5" damping="0.5" armature="0.00054"/>
          <geom pos="0.009 -0.037554 0.067306" group="0" quat="1 0 0 0" rgba="0.2 0.2 0.2 1" type="mesh" mesh="L_HipRoll_Link_1"/>
          <geom pos="0.009 -0.037554 0.067306" contype="0" conaffinity="0" group="1" quat="1 0 0 0" rgba="0.2 0.2 0.2 1" type="mesh" mesh="L_HipRoll_Link_1"/>
          <body name="L_Thigh_Link_1" pos="0.0237 0.02094 0">
            <inertial pos="-0.000427821 -0.0217942 -0.0711619" quat="0.999841 -0.0178259 0 0" mass="0.0567608" diaginertia="4.7e-05 4.10357e-05 1.29643e-05"/>
            <joint name="L_Thigh_Joint" pos="0 0 0" axis="0 1 0" limited="true" range="-0.7854 0.7854" stiffness="0.5" damping="0.5" armature="0.00054"/>
            <geom pos="-0.0147 -0.058494 0.067306" group="0" quat="1 0 0 0" rgba="0.2 0.2 0.2 1" type="mesh" mesh="L_Thigh_Link_1"/>
            <geom pos="-0.0147 -0.058494 0.067306" contype="0" conaffinity="0" group="1" quat="1 0 0 0" rgba="0.2 0.2 0.2 1" type="mesh" mesh="L_Thigh_Link_1"/>            
            <body name="L_Calf_Link_1" pos="-0.000421 -0.04194 -0.095807">
              <inertial pos="0.00910366 0.0210003 -0.0408459" quat="0.998332 0 0.0577405 0" mass="0.0236038" diaginertia="3.02321e-05 2.3e-05 1.27679e-05"/>
              <joint name="L_Calf_Joint" pos="0 0 0" axis="0 1 0" limited="true" range="-0.7854 0.7854" stiffness="0.5" damping="0.5" armature="0.00054"/>
              <geom pos="-0.014279 -0.016554 0.163113" group="0" rgba="0.2 0.2 0.2 1" type="mesh" mesh="L_Calf_Link_1"/>
              <geom pos="-0.014279 -0.016554 0.163113" contype="0" conaffinity="0" group="1" quat="1 0 0 0" rgba="0.2 0.2 0.2 1" type="mesh" mesh="L_Calf_Link_1"/>
              <body name="L_AnklePitch_Link_1" pos="0 0.042 -0.093">
                <inertial pos="-0.0204285 -0.0204932 0.016036" quat="0.479923 0.509544 0.520969 0.488498" mass="0.100883" diaginertia="8.50201e-05 6.71243e-05 3.48556e-05"/>
                <joint name="L_AnklePitch_Joint" pos="0 0 0" axis="0 1 0" limited="true" range="-0.7854 0.7854" stiffness="0.5" damping="0.5" armature="0.00054"/>
                <geom pos="-0.014279 -0.058554 0.256113" group="0" quat="1 0 0 0" rgba="0.2 0.2 0.2 1" type="mesh" mesh="L_AnklePitch_Link_1"/>
                <geom pos="-0.014279 -0.058554 0.256113" contype="0" conaffinity="0" group="1" quat="1 0 0 0" rgba="0.2 0.2 0.2 1" type="mesh" mesh="L_AnklePitch_Link_1"/>
                <body name="L_AnkleRoll_Link_1" pos="-0.0237 -0.02094 0">
                  <inertial pos="0.0387982 0.00540208 -0.0253465" quat="0.0328712 0.72177 0.0931947 0.685042" mass="0.0263339" diaginertia="2.72276e-05 2.19127e-05 8.85979e-06"/>
                  <joint name="L_AnkleRoll_Joint" pos="0 0 0" axis="1 0 0" limited="true" range="-0.7854 0.7854" stiffness="0.5" damping="0.5" armature="0.00054"/>
                  <geom pos="0.009421 -0.037614 0.256113" contype="0" conaffinity="0" group="1" quat="1 0 0 0" rgba="0.2 0.2 0.2 1" type="mesh" mesh="L_AnkleRoll_Link_1"/>
                  <geom pos="0.04355 0.007614 -0.028884" group="2" quat="1 0 0 0" type="box" size="0.05 0.0325 0.0015" rgba="0 0 0 0"/>
                </body>
              </body>
            </body>
          </body>
        </body>
      </body>
      <body name="R_HipYaw_Link_1" pos="0.014982 -0.03755 -0.03694">
        <inertial pos="-0.000220986 9.1293e-07 -0.0123156" quat="0.5 0.5 0.5 0.5" mass="0.00826277" diaginertia="4e-06 3e-06 1e-06"/>
        <joint name="R_HipYaw_Joint" pos="0 0 0" axis="0 0 1" limited="true" range="-0.7854 0.7854" stiffness="0.5" damping="0.5" armature="0.00054"/>
        <geom pos="-0.014982 0.03755 0.03694" contype="0" conaffinity="0" group="1" quat="1 0 0 0" rgba="0.2 0.2 0.2 1" type="mesh" mesh="R_HipYaw_Link_1"/>
        <body name="R_HipRoll_Link_1" pos="-0.024 4e-06 -0.030366">
          <inertial pos="0.003269 -0.000443693 -0.0160339" quat="0.520969 0.488498 0.479923 0.509544" mass="0.100864" diaginertia="8.50201e-05 6.71243e-05 3.48556e-05"/>
          <joint name="R_HipRoll_Joint" pos="0 0 0" axis="1 0 0" limited="true" range="-0.7854 0.7854" stiffness="0.5" damping="0.5" armature="0.00054"/>
          <geom pos="0.009018 0.037546 0.067306" group="0" quat="1 0 0 0" rgba="0.2 0.2 0.2 1" type="mesh" mesh="R_HipRoll_Link_1"/>
          <geom pos="0.009018 0.037546 0.067306" contype="0" conaffinity="0" group="1" quat="1 0 0 0" rgba="0.2 0.2 0.2 1" type="mesh" mesh="R_HipRoll_Link_1"/>
          <body name="R_Thigh_Link_1" pos="0.0237 -0.02094 0">
            <inertial pos="-0.000427705 0.0217948 -0.0711619" quat="0.999841 0.0178259 0 0" mass="0.0567608" diaginertia="4.7e-05 4.10357e-05 1.29643e-05"/>
            <joint name="R_Thigh_Joint" pos="0 0 0" axis="0 1 0" limited="true" range="-0.7854 0.7854" stiffness="0.5" damping="0.5" armature="0.00054"/>
            <geom pos="-0.014682 0.058486 0.067306" group="0" rgba="0.2 0.2 0.2 1" type="mesh" mesh="R_Thigh_Link_1"/>
            <geom pos="-0.014682 0.058486 0.067306" contype="0" conaffinity="0" group="1" quat="1 0 0 0" rgba="0.2 0.2 0.2 1" type="mesh" mesh="R_Thigh_Link_1"/>
            <body name="R_Calf_Link_1" pos="-0.000421 0.04194 -0.095807">
              <inertial pos="0.00910377 -0.0209997 -0.0408459" quat="0.998893 0 0.047038 0" mass="0.0295048" diaginertia="3.71888e-05 2.8e-05 1.58112e-05"/>
              <joint name="R_Calf_Joint" pos="0 0 0" axis="0 1 0" limited="true" range="-0.7854 0.7854" stiffness="0.5" damping="0.5" armature="0.00054"/>
              <geom pos="-0.014261 0.016546 0.163113" group="0" rgba="0.2 0.2 0.2 1" type="mesh" mesh="R_Calf_Link_1"/>
              <geom pos="-0.014261 0.016546 0.163113" contype="0" conaffinity="0" group="1" quat="1 0 0 0" rgba="0.2 0.2 0.2 1" type="mesh" mesh="R_Calf_Link_1"/>
              <body name="R_AnklePitch_Link_1" pos="0 -0.042 -0.093">
                <inertial pos="-0.0204291 0.0204934 0.0160378" quat="0.488498 0.520969 0.509544 0.479923" mass="0.100895" diaginertia="8.50201e-05 6.71243e-05 3.48556e-05"/>
                <joint name="R_AnklePitch_Joint" pos="0 0 0" axis="0 1 0" limited="true" range="-0.7854 0.7854" stiffness="0.5" damping="0.5" armature="0.00054"/>
                <geom pos="-0.014261 0.058546 0.256113" group="0" quat="1 0 0 0" rgba="0.2 0.2 0.2 1" type="mesh" mesh="R_AnklePitch_Link_1"/>
                <geom pos="-0.014261 0.058546 0.256113" contype="0" conaffinity="0" group="1" quat="1 0 0 0" rgba="0.2 0.2 0.2 1" type="mesh" mesh="R_AnklePitch_Link_1"/>
                <body name="R_AnkleRoll_Link_1" pos="-0.0237 0.02094 -1.8e-05">
                  <inertial pos="0.0387983 -0.00540153 -0.0253464" quat="-0.0328712 0.72177 -0.0931947 0.685042" mass="0.0263339" diaginertia="2.72276e-05 2.19127e-05 8.85979e-06"/>
                  <joint name="R_AnkleRoll_Joint" pos="0 0 0" axis="1 0 0" limited="true" range="-0.7854 0.7854" stiffness="0.5" damping="0.5" armature="0.00054"/>
                  <geom pos="0.009439 0.037606 0.256131" contype="0" conaffinity="0" group="1" quat="1 0 0 0" rgba="0.2 0.2 0.2 1" type="mesh" mesh="R_AnkleRoll_Link_1"/>
                  <geom pos="0.04355 -0.007614 -0.028884" group="2" quat="1 0 0 0" type="box" size="0.05 0.0325 0.0015" rgba="0 0 0 0"/>
                </body>
              </body>
            </body>
          </body>
        </body>
      </body>
    </body>
    <geom name="floor" size="0 0 0.01" type="plane" material="groundplane"
          contype="1" conaffinity="1" priority="1" friction="0.6" condim="3"/>
    <light diffuse=".5 .5 .5" pos="-3 -3 5" dir="3 3 -5" castshadow="true"/>
  </worldbody>

  <!-- ctrl = motor input torque [N·m] (before gear reduction).
       Dynamixel gear=254, output stall torque=1.8 N·m
         → motor input torque = 1.8 / 254 ≈ 0.00709 N·m
         → joint torque = ctrl × gear = 0.00709 × 254 = 1.8 N·m  -->
  <actuator>
    <motor name="L_HipYaw_Joint" joint="L_HipYaw_Joint" gear="254" ctrllimited="true" ctrlrange="-0.00709 0.00709"/>
    <motor name="L_HipRoll_Joint" joint="L_HipRoll_Joint" gear="254" ctrllimited="true" ctrlrange="-0.00709 0.00709"/>
    <motor name="L_Thigh_Joint" joint="L_Thigh_Joint" gear="254" ctrllimited="true" ctrlrange="-0.00709 0.00709"/>
    <motor name="L_Calf_Joint" joint="L_Calf_Joint" gear="254" ctrllimited="true" ctrlrange="-0.00709 0.00709"/>
    <motor name="L_AnklePitch_Joint" joint="L_AnklePitch_Joint" gear="254" ctrllimited="true" ctrlrange="-0.00709 0.00709"/>
    <motor name="L_AnkleRoll_Joint" joint="L_AnkleRoll_Joint" gear="254" ctrllimited="true" ctrlrange="-0.00709 0.00709"/>
    <motor name="R_HipYaw_Joint" joint="R_HipYaw_Joint" gear="254" ctrllimited="true" ctrlrange="-0.00709 0.00709"/>
    <motor name="R_HipRoll_Joint" joint="R_HipRoll_Joint" gear="254" ctrllimited="true" ctrlrange="-0.00709 0.00709"/>
    <motor name="R_Thigh_Joint" joint="R_Thigh_Joint" gear="254" ctrllimited="true" ctrlrange="-0.00709 0.00709"/>
    <motor name="R_Calf_Joint" joint="R_Calf_Joint" gear="254" ctrllimited="true" ctrlrange="-0.00709 0.00709"/>
    <motor name="R_AnklePitch_Joint" joint="R_AnklePitch_Joint" gear="254" ctrllimited="true" ctrlrange="-0.00709 0.00709"/>
    <motor name="R_AnkleRoll_Joint" joint="R_AnkleRoll_Joint" gear="254" ctrllimited="true" ctrlrange="-0.00709 0.00709"/>
  </actuator>
  <visual>
    <headlight diffuse="0.6 0.6 0.6" ambient="0.1 0.1 0.1" specular="0.9 0.9 0.9"/>
    <rgba haze="0.15 0.25 0.35 1"/>
    <global azimuth="-140" elevation="-40" offwidth="2080" offheight="1000"/>
  </visual>
</mujoco>
